<?xml version="1.0" encoding="UTF-8"?>
<!DOCTYPE html PUBLIC "-//W3C//DTD XHTML 1.0 Strict//EN" "http://www.w3.org/TR/xhtml1/DTD/xhtml1-strict.dtd">
<html xmlns="http://www.w3.org/1999/xhtml">
<head>
    <title>py0330测试报告</title>
    <meta name="generator" content="HTMLTestRunner 0.8.2.2"/>
    <meta http-equiv="Content-Type" content="text/html; charset=UTF-8"/>
    <link href="http://libs.baidu.com/bootstrap/3.0.3/css/bootstrap.min.css" rel="stylesheet">
    <script src="http://libs.baidu.com/jquery/2.0.0/jquery.min.js"></script>
    <script src="http://libs.baidu.com/bootstrap/3.0.3/js/bootstrap.min.js"></script>
    
<style type="text/css" media="screen">
body        { font-family: Microsoft YaHei,Tahoma,arial,helvetica,sans-serif;padding: 20px; font-size: 120%; }
table       { font-size: 100%; }
/* -- heading ---------------------------------------------------------------------- */
.heading {
    margin-top: 0ex;
    margin-bottom: 1ex;
}
.heading .description {
    margin-top: 4ex;
    margin-bottom: 6ex;
}
/* -- report ------------------------------------------------------------------------ */
#total_row  { font-weight: bold; }
.passCase   { color: #5cb85c; }
.failCase   { color: #d9534f; font-weight: bold; }
.errorCase  { color: #f0ad4e; font-weight: bold; }
.hiddenRow  { display: none; }
.testcase   { margin-left: 2em; }
</style>

</head>
<body >
<script language="javascript" type="text/javascript">
output_list = Array();
/*level 调整增加只显示通过用例的分类 --Findyou
0:Summary //all hiddenRow
1:Failed  //pt hiddenRow, ft none
2:Pass    //pt none, ft hiddenRow
3:All     //pt none, ft none
*/
function showCase(level) {
    trs = document.getElementsByTagName("tr");
    for (var i = 0; i < trs.length; i++) {
        tr = trs[i];
        id = tr.id;
        if (id.substr(0,2) == 'ft') {
            if (level == 2 || level == 0 ) {
                tr.className = 'hiddenRow';
            }
            else {
                tr.className = '';
            }
        }
        if (id.substr(0,2) == 'pt') {
            if (level < 2) {
                tr.className = 'hiddenRow';
            }
            else {
                tr.className = '';
            }
        }
    }
    //加入【详细】切换文字变化 --Findyou
    detail_class=document.getElementsByClassName('detail');
	//console.log(detail_class.length)
	if (level == 3) {
		for (var i = 0; i < detail_class.length; i++){
			detail_class[i].innerHTML="收起"
		}
	}
	else{
			for (var i = 0; i < detail_class.length; i++){
			detail_class[i].innerHTML="详细"
		}
	}
}
function showClassDetail(cid, count) {
    var id_list = Array(count);
    var toHide = 1;
    for (var i = 0; i < count; i++) {
        //ID修改 点 为 下划线 -Findyou
        tid0 = 't' + cid.substr(1) + '_' + (i+1);
        tid = 'f' + tid0;
        tr = document.getElementById(tid);
        if (!tr) {
            tid = 'p' + tid0;
            tr = document.getElementById(tid);
        }
        id_list[i] = tid;
        if (tr.className) {
            toHide = 0;
        }
    }
    for (var i = 0; i < count; i++) {
        tid = id_list[i];
        //修改点击无法收起的BUG，加入【详细】切换文字变化 --Findyou
        if (toHide) {
            document.getElementById(tid).className = 'hiddenRow';
            document.getElementById(cid).innerText = "详细"
        }
        else {
            document.getElementById(tid).className = '';
            document.getElementById(cid).innerText = "收起"
        }
    }
}
function html_escape(s) {
    s = s.replace(/&/g,'&amp;');
    s = s.replace(/</g,'&lt;');
    s = s.replace(/>/g,'&gt;');
    return s;
}
</script>
<div class='heading'>
<h1 style="font-family: Microsoft YaHei">py0330测试报告</h1>
<p class='attribute'><strong>测试人员 : </strong> shanshan</p>
<p class='attribute'><strong>开始时间 : </strong> 2019-03-31 09:38:13</p>
<p class='attribute'><strong>合计耗时 : </strong> 0:00:05.594000</p>
<p class='attribute'><strong>测试结果 : </strong> 共 5，错误 5，通过率= 0.00%</p>

<p class='description'>14的测试报告</p>
</div>


<p id='show_detail_line'>
<a class="btn btn-primary" href='javascript:showCase(0)'>概要{ 0.00% }</a>
<a class="btn btn-danger" href='javascript:showCase(1)'>失败{ 0 }</a>
<a class="btn btn-success" href='javascript:showCase(2)'>通过{ 0 }</a>
<a class="btn btn-info" href='javascript:showCase(3)'>所有{ 5 }</a>
</p>
<table id='result_table' class="table table-condensed table-bordered table-hover">
<colgroup>
<col align='left' />
<col align='right' />
<col align='right' />
<col align='right' />
<col align='right' />
<col align='right' />
</colgroup>
<tr id='header_row' class="text-center success" style="font-weight: bold;font-size: 16px;">
    <td>用例集/测试用例</td>
    <td>总计</td>
    <td>通过</td>
    <td>失败</td>
    <td>错误</td>
    <td>详细</td>
</tr>

<tr class='errorClass warning'>
    <td>API_6.test_case.test_login.TestHttpRequest</td>
    <td class="text-center">5</td>
    <td class="text-center">0</td>
    <td class="text-center">0</td>
    <td class="text-center">5</td>
    <td class="text-center"><a href="javascript:showClassDetail('c1',5)" class="detail" id='c1'>详细</a></td>
</tr>

<tr id='ft1_1' class='none'>
    <td class='errorCase'><div class='testcase'>test_cases_1</div></td>
    <td colspan='5' align='center'>
    <!--默认收起错误信息 -Findyou
    <button id='btn_ft1_1' type="button"  class="btn btn-danger btn-xs collapsed" data-toggle="collapse" data-target='#div_ft1_1'>错误</button>
    <div id='div_ft1_1' class="collapse">  -->
    <!-- 默认展开错误信息 -Findyou -->
    <button id='btn_ft1_1' type="button"  class="btn btn-danger btn-xs" data-toggle="collapse" data-target='#div_ft1_1'>错误</button>
    <div id='div_ft1_1' class="collapse in" align="left">
    <pre>
    
ft1_1: key: phone
key: pwd
[2019-03-31 09:38:13,598]-[INFO]-my_log.py-[日志信息]:**************************************
[2019-03-31 09:38:13,600]-[INFO]-my_log.py-[日志信息]:正在执行Login模块的第1条用例:正常登录
[2019-03-31 09:38:13,602]-[INFO]-my_log.py-[日志信息]:请求的测试数据是{'CaseId': 1, 'Module': 'Login', 'Title': '正常登录', 'Method': 'GET', 'Url': 'http://47.107.168.87:8080/futureloan/mvc/api/member/login', 'Param': "{'mobilephone':'#phone#','pwd':'#pwd#'}", 'Sql': None, 'ExpectedResult': "{'status': 1, 'code': '10001', 'data': None, 'msg': '登录成功'}"}
正在发起get请求
执行get请求报错，错误是HTTPConnectionPool(host='47.107.168.87', port=8080): Max retries exceeded with url: /futureloan/mvc/api/member/login?mobilephone=15382876192&amp;pwd=123456 (Caused by NewConnectionError('&lt;urllib3.connection.HTTPConnection object at 0x0000000004A532E8&gt;: Failed to establish a new connection: [WinError 10061] 由于目标计算机积极拒绝，无法连接。'))
状态码: Error:get请求报错HTTPConnectionPool(host='47.107.168.87', port=8080): Max retries exceeded with url: /futureloan/mvc/api/member/login?mobilephone=15382876192&amp;pwd=123456 (Caused by NewConnectionError('&lt;urllib3.connection.HTTPConnection object at 0x0000000004A532E8&gt;: Failed to establish a new connection: [WinError 10061] 由于目标计算机积极拒绝，无法连接。'))
[2019-03-31 09:38:14,687]-[INFO]-my_log.py-[日志信息]:**********开始写入数据***********
已结束测试啦！
Traceback (most recent call last):
  File ".\API_6\test_case\test_login.py", line 51, in test_cases
    self.assertEqual(eval(case['ExpectedResult']), resp.json())#断言：判断期望结果和实际结果是否一致
AttributeError: 'str' object has no attribute 'json'

During handling of the above exception, another exception occurred:

Traceback (most recent call last):
  File "D:\Program Files\Python37\lib\site-packages\ddt.py", line 145, in wrapper
    return func(self, *args, **kwargs)
  File ".\API_6\test_case\test_login.py", line 59, in test_cases
    self.t.write_back(case['CaseId']+1,9,str(resp.json()))#写入实际结果
AttributeError: 'str' object has no attribute 'json'


    </pre>
    </div>
    </td>
</tr>

<tr id='ft1_2' class='none'>
    <td class='errorCase'><div class='testcase'>test_cases_2</div></td>
    <td colspan='5' align='center'>
    <!--默认收起错误信息 -Findyou
    <button id='btn_ft1_2' type="button"  class="btn btn-danger btn-xs collapsed" data-toggle="collapse" data-target='#div_ft1_2'>错误</button>
    <div id='div_ft1_2' class="collapse">  -->
    <!-- 默认展开错误信息 -Findyou -->
    <button id='btn_ft1_2' type="button"  class="btn btn-danger btn-xs" data-toggle="collapse" data-target='#div_ft1_2'>错误</button>
    <div id='div_ft1_2' class="collapse in" align="left">
    <pre>
    
ft1_2: key: pwd
[2019-03-31 09:38:14,697]-[INFO]-my_log.py-[日志信息]:**************************************
[2019-03-31 09:38:14,702]-[INFO]-my_log.py-[日志信息]:正在执行Login模块的第2条用例:手机号码为空，密码正确
[2019-03-31 09:38:14,707]-[INFO]-my_log.py-[日志信息]:请求的测试数据是{'CaseId': 2, 'Module': 'Login', 'Title': '手机号码为空，密码正确', 'Method': 'POST', 'Url': 'http://47.107.168.87:8080/futureloan/mvc/api/member/login', 'Param': "{'mobilephone':'','pwd':'#pwd#'}", 'Sql': None, 'ExpectedResult': "{'status': 0, 'code': '20103', 'data': None, 'msg': '手机号不能为空'}"}
正在发起post请求
执行post请求报错，错误是HTTPConnectionPool(host='47.107.168.87', port=8080): Max retries exceeded with url: /futureloan/mvc/api/member/login (Caused by NewConnectionError('&lt;urllib3.connection.HTTPConnection object at 0x0000000004A3D940&gt;: Failed to establish a new connection: [WinError 10061] 由于目标计算机积极拒绝，无法连接。'))
状态码: Error:get请求报错HTTPConnectionPool(host='47.107.168.87', port=8080): Max retries exceeded with url: /futureloan/mvc/api/member/login (Caused by NewConnectionError('&lt;urllib3.connection.HTTPConnection object at 0x0000000004A3D940&gt;: Failed to establish a new connection: [WinError 10061] 由于目标计算机积极拒绝，无法连接。'))
[2019-03-31 09:38:15,809]-[INFO]-my_log.py-[日志信息]:**********开始写入数据***********
已结束测试啦！
Traceback (most recent call last):
  File ".\API_6\test_case\test_login.py", line 51, in test_cases
    self.assertEqual(eval(case['ExpectedResult']), resp.json())#断言：判断期望结果和实际结果是否一致
AttributeError: 'str' object has no attribute 'json'

During handling of the above exception, another exception occurred:

Traceback (most recent call last):
  File "D:\Program Files\Python37\lib\site-packages\ddt.py", line 145, in wrapper
    return func(self, *args, **kwargs)
  File ".\API_6\test_case\test_login.py", line 59, in test_cases
    self.t.write_back(case['CaseId']+1,9,str(resp.json()))#写入实际结果
AttributeError: 'str' object has no attribute 'json'


    </pre>
    </div>
    </td>
</tr>

<tr id='ft1_3' class='none'>
    <td class='errorCase'><div class='testcase'>test_cases_3</div></td>
    <td colspan='5' align='center'>
    <!--默认收起错误信息 -Findyou
    <button id='btn_ft1_3' type="button"  class="btn btn-danger btn-xs collapsed" data-toggle="collapse" data-target='#div_ft1_3'>错误</button>
    <div id='div_ft1_3' class="collapse">  -->
    <!-- 默认展开错误信息 -Findyou -->
    <button id='btn_ft1_3' type="button"  class="btn btn-danger btn-xs" data-toggle="collapse" data-target='#div_ft1_3'>错误</button>
    <div id='div_ft1_3' class="collapse in" align="left">
    <pre>
    
ft1_3: key: phone
[2019-03-31 09:38:15,814]-[INFO]-my_log.py-[日志信息]:**************************************
[2019-03-31 09:38:15,817]-[INFO]-my_log.py-[日志信息]:正在执行Login模块的第3条用例:手机号正确，密码为空
[2019-03-31 09:38:15,820]-[INFO]-my_log.py-[日志信息]:请求的测试数据是{'CaseId': 3, 'Module': 'Login', 'Title': '手机号正确，密码为空', 'Method': 'GET', 'Url': 'http://47.107.168.87:8080/futureloan/mvc/api/member/login', 'Param': "{'mobilephone':'#phone#','pwd':''}", 'Sql': None, 'ExpectedResult': "{'status': 0, 'code': '20103', 'data': None, 'msg': '密码不能为空'}"}
正在发起get请求
执行get请求报错，错误是HTTPConnectionPool(host='47.107.168.87', port=8080): Max retries exceeded with url: /futureloan/mvc/api/member/login?mobilephone=15382876192&amp;pwd= (Caused by NewConnectionError('&lt;urllib3.connection.HTTPConnection object at 0x0000000004996630&gt;: Failed to establish a new connection: [WinError 10061] 由于目标计算机积极拒绝，无法连接。'))
状态码: Error:get请求报错HTTPConnectionPool(host='47.107.168.87', port=8080): Max retries exceeded with url: /futureloan/mvc/api/member/login?mobilephone=15382876192&amp;pwd= (Caused by NewConnectionError('&lt;urllib3.connection.HTTPConnection object at 0x0000000004996630&gt;: Failed to establish a new connection: [WinError 10061] 由于目标计算机积极拒绝，无法连接。'))
[2019-03-31 09:38:16,922]-[INFO]-my_log.py-[日志信息]:**********开始写入数据***********
已结束测试啦！
Traceback (most recent call last):
  File ".\API_6\test_case\test_login.py", line 51, in test_cases
    self.assertEqual(eval(case['ExpectedResult']), resp.json())#断言：判断期望结果和实际结果是否一致
AttributeError: 'str' object has no attribute 'json'

During handling of the above exception, another exception occurred:

Traceback (most recent call last):
  File "D:\Program Files\Python37\lib\site-packages\ddt.py", line 145, in wrapper
    return func(self, *args, **kwargs)
  File ".\API_6\test_case\test_login.py", line 59, in test_cases
    self.t.write_back(case['CaseId']+1,9,str(resp.json()))#写入实际结果
AttributeError: 'str' object has no attribute 'json'


    </pre>
    </div>
    </td>
</tr>

<tr id='ft1_4' class='none'>
    <td class='errorCase'><div class='testcase'>test_cases_4</div></td>
    <td colspan='5' align='center'>
    <!--默认收起错误信息 -Findyou
    <button id='btn_ft1_4' type="button"  class="btn btn-danger btn-xs collapsed" data-toggle="collapse" data-target='#div_ft1_4'>错误</button>
    <div id='div_ft1_4' class="collapse">  -->
    <!-- 默认展开错误信息 -Findyou -->
    <button id='btn_ft1_4' type="button"  class="btn btn-danger btn-xs" data-toggle="collapse" data-target='#div_ft1_4'>错误</button>
    <div id='div_ft1_4' class="collapse in" align="left">
    <pre>
    
ft1_4: key: pwd
[2019-03-31 09:38:16,931]-[INFO]-my_log.py-[日志信息]:**************************************
[2019-03-31 09:38:16,936]-[INFO]-my_log.py-[日志信息]:正在执行Login模块的第4条用例:手机号错误，密码正确
[2019-03-31 09:38:16,942]-[INFO]-my_log.py-[日志信息]:请求的测试数据是{'CaseId': 4, 'Module': 'Login', 'Title': '手机号错误，密码正确', 'Method': 'POST', 'Url': 'http://47.107.168.87:8080/futureloan/mvc/api/member/login', 'Param': "{'mobilephone':'1538287619','pwd':'#pwd#'}", 'Sql': None, 'ExpectedResult': "{'status': 0, 'code': '20111', 'data': None, 'msg': '用户名或密码错误'}"}
正在发起post请求
执行post请求报错，错误是HTTPConnectionPool(host='47.107.168.87', port=8080): Max retries exceeded with url: /futureloan/mvc/api/member/login (Caused by NewConnectionError('&lt;urllib3.connection.HTTPConnection object at 0x00000000049F2780&gt;: Failed to establish a new connection: [WinError 10061] 由于目标计算机积极拒绝，无法连接。'))
状态码: Error:get请求报错HTTPConnectionPool(host='47.107.168.87', port=8080): Max retries exceeded with url: /futureloan/mvc/api/member/login (Caused by NewConnectionError('&lt;urllib3.connection.HTTPConnection object at 0x00000000049F2780&gt;: Failed to establish a new connection: [WinError 10061] 由于目标计算机积极拒绝，无法连接。'))
[2019-03-31 09:38:18,039]-[INFO]-my_log.py-[日志信息]:**********开始写入数据***********
已结束测试啦！
Traceback (most recent call last):
  File ".\API_6\test_case\test_login.py", line 51, in test_cases
    self.assertEqual(eval(case['ExpectedResult']), resp.json())#断言：判断期望结果和实际结果是否一致
AttributeError: 'str' object has no attribute 'json'

During handling of the above exception, another exception occurred:

Traceback (most recent call last):
  File "D:\Program Files\Python37\lib\site-packages\ddt.py", line 145, in wrapper
    return func(self, *args, **kwargs)
  File ".\API_6\test_case\test_login.py", line 59, in test_cases
    self.t.write_back(case['CaseId']+1,9,str(resp.json()))#写入实际结果
AttributeError: 'str' object has no attribute 'json'


    </pre>
    </div>
    </td>
</tr>

<tr id='ft1_5' class='none'>
    <td class='errorCase'><div class='testcase'>test_cases_5</div></td>
    <td colspan='5' align='center'>
    <!--默认收起错误信息 -Findyou
    <button id='btn_ft1_5' type="button"  class="btn btn-danger btn-xs collapsed" data-toggle="collapse" data-target='#div_ft1_5'>错误</button>
    <div id='div_ft1_5' class="collapse">  -->
    <!-- 默认展开错误信息 -Findyou -->
    <button id='btn_ft1_5' type="button"  class="btn btn-danger btn-xs" data-toggle="collapse" data-target='#div_ft1_5'>错误</button>
    <div id='div_ft1_5' class="collapse in" align="left">
    <pre>
    
ft1_5: key: phone
[2019-03-31 09:38:18,048]-[INFO]-my_log.py-[日志信息]:**************************************
[2019-03-31 09:38:18,052]-[INFO]-my_log.py-[日志信息]:正在执行Login模块的第5条用例:手机号正确，密码错误
[2019-03-31 09:38:18,058]-[INFO]-my_log.py-[日志信息]:请求的测试数据是{'CaseId': 5, 'Module': 'Login', 'Title': '手机号正确，密码错误', 'Method': 'GET', 'Url': 'http://47.107.168.87:8080/futureloan/mvc/api/member/login', 'Param': "{'mobilephone':'#phone#','pwd':'654321'}", 'Sql': None, 'ExpectedResult': "{'status': 0, 'code': '20111', 'data': None, 'msg': '用户名或密码错误'}"}
正在发起get请求
执行get请求报错，错误是HTTPConnectionPool(host='47.107.168.87', port=8080): Max retries exceeded with url: /futureloan/mvc/api/member/login?mobilephone=15382876192&amp;pwd=654321 (Caused by NewConnectionError('&lt;urllib3.connection.HTTPConnection object at 0x00000000049B6828&gt;: Failed to establish a new connection: [WinError 10061] 由于目标计算机积极拒绝，无法连接。'))
状态码: Error:get请求报错HTTPConnectionPool(host='47.107.168.87', port=8080): Max retries exceeded with url: /futureloan/mvc/api/member/login?mobilephone=15382876192&amp;pwd=654321 (Caused by NewConnectionError('&lt;urllib3.connection.HTTPConnection object at 0x00000000049B6828&gt;: Failed to establish a new connection: [WinError 10061] 由于目标计算机积极拒绝，无法连接。'))
[2019-03-31 09:38:19,185]-[INFO]-my_log.py-[日志信息]:**********开始写入数据***********
已结束测试啦！
Traceback (most recent call last):
  File ".\API_6\test_case\test_login.py", line 51, in test_cases
    self.assertEqual(eval(case['ExpectedResult']), resp.json())#断言：判断期望结果和实际结果是否一致
AttributeError: 'str' object has no attribute 'json'

During handling of the above exception, another exception occurred:

Traceback (most recent call last):
  File "D:\Program Files\Python37\lib\site-packages\ddt.py", line 145, in wrapper
    return func(self, *args, **kwargs)
  File ".\API_6\test_case\test_login.py", line 59, in test_cases
    self.t.write_back(case['CaseId']+1,9,str(resp.json()))#写入实际结果
AttributeError: 'str' object has no attribute 'json'


    </pre>
    </div>
    </td>
</tr>

<tr id='total_row' class="text-center active">
    <td>总计</td>
    <td>5</td>
    <td>0</td>
    <td>0</td>
    <td>5</td>
    <td>通过率：0.00%</td>
</tr>
</table>

<div id='ending'>&nbsp;</div>
    <div style=" position:fixed;right:50px; bottom:30px; width:20px; height:20px;cursor:pointer">
    <a href="#"><span class="glyphicon glyphicon-eject" style = "font-size:30px;" aria-hidden="true">
    </span></a></div>
    
</body>
</html>
